{"uuid": "b4c54cde-eafa-4a28-9474-7c446ca60f5d", "children": ["b0b0aba9-be7a-410f-919e-6ba9b380df11"], "befores": [{"name": "driver", "status": "broken", "statusDetails": {"message": "selenium.common.exceptions.InvalidArgumentException: Message: Requested environment is not available\n\n", "trace": "  File \"/usr/local/lib/python3.8/site-packages/pluggy/_callers.py\", line 39, in _multicall\n    res = hook_impl.function(*args)\n  File \"/usr/local/lib/python3.8/site-packages/_pytest/fixtures.py\", line 1122, in pytest_fixture_setup\n    result = call_fixture_func(fixturefunc, request, kwargs)\n  File \"/usr/local/lib/python3.8/site-packages/_pytest/fixtures.py\", line 917, in call_fixture_func\n    fixture_result = next(generator)\n  File \"/final_project/code/ui_myapp/tools/fixtures.py\", line 22, in driver\n    driver = webdriver.Remote(\n  File \"/usr/local/lib/python3.8/site-packages/selenium/webdriver/remote/webdriver.py\", line 269, in __init__\n    self.start_session(capabilities, browser_profile)\n  File \"/usr/local/lib/python3.8/site-packages/selenium/webdriver/remote/webdriver.py\", line 360, in start_session\n    response = self.execute(Command.NEW_SESSION, parameters)\n  File \"/usr/local/lib/python3.8/site-packages/selenium/webdriver/remote/webdriver.py\", line 425, in execute\n    self.error_handler.check_response(response)\n  File \"/usr/local/lib/python3.8/site-packages/selenium/webdriver/remote/errorhandler.py\", line 247, in check_response\n    raise exception_class(message, screen, stacktrace)\n"}, "start": 1653226665169, "stop": 1653226665172}], "start": 1653226665169, "stop": 1653226665213}