WARNING  urllib3.connectionpool:connectionpool.py:810 Retrying (Retry(total=2, connect=None, read=None, redirect=None, status=None)) after connection broken by 'NewConnectionError('<urllib3.connection.HTTPConnection object at 0x7fccf9bc47c0>: Failed to establish a new connection: [Errno 111] Connection refused')': /wd/hub/session
WARNING  urllib3.connectionpool:connectionpool.py:810 Retrying (Retry(total=1, connect=None, read=None, redirect=None, status=None)) after connection broken by 'NewConnectionError('<urllib3.connection.HTTPConnection object at 0x7fccf9bc4e20>: Failed to establish a new connection: [Errno 111] Connection refused')': /wd/hub/session
WARNING  urllib3.connectionpool:connectionpool.py:810 Retrying (Retry(total=0, connect=None, read=None, redirect=None, status=None)) after connection broken by 'NewConnectionError('<urllib3.connection.HTTPConnection object at 0x7fccf9e003a0>: Failed to establish a new connection: [Errno 111] Connection refused')': /wd/hub/session