{"uuid": "3f542773-8de6-4d02-ab70-be4579f10e43", "children": ["c46dd85b-8346-4535-b195-27c06021fc71"], "befores": [{"name": "driver", "status": "broken", "statusDetails": {"message": "urllib3.exceptions.MaxRetryError: HTTPConnectionPool(host='my_app', port=4444): Max retries exceeded with url: /wd/hub/session (Caused by NewConnectionError('<urllib3.connection.HTTPConnection object at 0x7fccf9c17a30>: Failed to establish a new connection: [Errno 111] Connection refused'))\n", "trace": "  File \"/usr/local/lib/python3.8/site-packages/pluggy/_callers.py\", line 39, in _multicall\n    res = hook_impl.function(*args)\n  File \"/usr/local/lib/python3.8/site-packages/_pytest/fixtures.py\", line 1122, in pytest_fixture_setup\n    result = call_fixture_func(fixturefunc, request, kwargs)\n  File \"/usr/local/lib/python3.8/site-packages/_pytest/fixtures.py\", line 917, in call_fixture_func\n    fixture_result = next(generator)\n  File \"/final_project/code/ui_myapp/tools/fixtures.py\", line 22, in driver\n    driver = webdriver.Remote(\n  File \"/usr/local/lib/python3.8/site-packages/selenium/webdriver/remote/webdriver.py\", line 269, in __init__\n    self.start_session(capabilities, browser_profile)\n  File \"/usr/local/lib/python3.8/site-packages/selenium/webdriver/remote/webdriver.py\", line 360, in start_session\n    response = self.execute(Command.NEW_SESSION, parameters)\n  File \"/usr/local/lib/python3.8/site-packages/selenium/webdriver/remote/webdriver.py\", line 423, in execute\n    response = self.command_executor.execute(driver_command, params)\n  File \"/usr/local/lib/python3.8/site-packages/selenium/webdriver/remote/remote_connection.py\", line 316, in execute\n    return self._request(command_info[0], url, body=data)\n  File \"/usr/local/lib/python3.8/site-packages/selenium/webdriver/remote/remote_connection.py\", line 338, in _request\n    resp = self._conn.request(method, url, body=body, headers=headers)\n  File \"/usr/local/lib/python3.8/site-packages/urllib3/request.py\", line 78, in request\n    return self.request_encode_body(\n  File \"/usr/local/lib/python3.8/site-packages/urllib3/request.py\", line 170, in request_encode_body\n    return self.urlopen(method, url, **extra_kw)\n  File \"/usr/local/lib/python3.8/site-packages/urllib3/poolmanager.py\", line 375, in urlopen\n    response = conn.urlopen(method, u.request_uri, **kw)\n  File \"/usr/local/lib/python3.8/site-packages/urllib3/connectionpool.py\", line 813, in urlopen\n    return self.urlopen(\n  File \"/usr/local/lib/python3.8/site-packages/urllib3/connectionpool.py\", line 813, in urlopen\n    return self.urlopen(\n  File \"/usr/local/lib/python3.8/site-packages/urllib3/connectionpool.py\", line 813, in urlopen\n    return self.urlopen(\n  File \"/usr/local/lib/python3.8/site-packages/urllib3/connectionpool.py\", line 785, in urlopen\n    retries = retries.increment(\n  File \"/usr/local/lib/python3.8/site-packages/urllib3/util/retry.py\", line 592, in increment\n    raise MaxRetryError(_pool, url, error or ResponseError(cause))\n"}, "start": 1653225588875, "stop": 1653225588878}], "start": 1653225588875, "stop": 1653225589069}